Workbook

Sheet Roll Up Template
N1: Production Month:
D5: Wellhead Production | I5: Recycle m3 | J5: Shipments | M5: Fluid Out m3 | N5: Fluid In m3
A6: Date | B6: Hours | C6: Hours | D6: Gross Prod | E6: Net Oil | F6: Net Oil | G6: Net Sand | H6: Net Water | O6: Foam Loss
B7: On | C7: Down | D7: m3 | E7: m3 | F7: BBLS | G7: m3 | H7: m3 | J7: Net Oil (m3) | K7: Water (m3) | L7: Sand (m3)
A8: 1 | B8: =#REF!+#REF!+#REF!+#REF!+#REF!+#REF!+#REF!+#REF!+#REF!+#REF!+#REF!+#REF!+'Well Template'!B7+#REF!+#REF!+#REF!+#REF!+#REF!+#REF!+#REF!+#REF!+#REF!+#REF!+#REF!+#REF! -> #REF! | C8: ='Summary Template'!AA184 -> #REF! | D8: =#REF!+#REF!+#REF!+#REF!+#REF!+#REF!+#REF!+#REF!+#REF!+#REF!+#REF!+#REF!+'Well Template'!H7+#REF!+#REF!+#REF!+#REF!+#REF!+#REF!+#REF!+#REF!+#REF!+#REF!+#REF!+#REF! -> #REF! | E8: ='Summary Template'!AA4 -> #REF! | F8: =+E8*6.2898 -> #REF! | G8: ='Summary Template'!AA75 -> #REF! | H8: ='Summary Template'!AA112 -> #REF! | I8: =#REF!+#REF!+#REF!+#REF!+#REF!+#REF!+#REF!+#REF!+#REF!+#REF!+#REF!+#REF!+'Well Template'!L7+#REF!+#REF!+#REF!+#REF!+#REF!+#REF!+#REF!+#REF!+#REF!+#REF!+#REF!+#REF! -> #REF! | J8: ='Summary Template'!AA39 -> #REF! | K8: ='Summary Template'!AA148 -> #REF! | L8: =#REF!+#REF!+#REF!+#REF!+#REF!+#REF!+#REF!+#REF!+#REF!+#REF!+#REF!+#REF!+'Well Template'!R7+#REF!+#REF!+#REF!+#REF!+#REF!+#REF!+#REF!+#REF!+#REF!+#REF!+#REF!+#REF! -> #REF! | M8: =#REF!+#REF!+#REF!+#REF!+#REF!+#REF!+#REF!+#REF!+#REF!+#REF!+#REF!+#REF!+'Well Template'!#REF!+#REF!+#REF!+#REF!+#REF!+#REF!+#REF!+#REF!+#REF!+#REF!+#REF!+#REF!+#REF! -> #REF! | N8: =#REF!+#REF!+#REF!+#REF!+#REF!+#REF!+#REF!+#REF!+#REF!+#REF!+#REF!+#REF!+'Well Template'!U7+#REF!+#REF!+#REF!+#REF!+#REF!+#REF!+#REF!+#REF!+#REF!+#REF!+#REF!+#REF! -> #REF! | O8: =#REF!+#REF!+#REF!+#REF!+#REF!+#REF!+#REF!+#REF!+#REF!+#REF!+#REF!+#REF!+'Well Template'!V7+#REF!+#REF!+#REF!+#REF!+#REF!+#REF!+#REF!+#REF!+#REF!+#REF!+#REF!+#REF! -> #REF!
A9: =+A8+1 -> 2 | B9: =#REF!+#REF!+#REF!+#REF!+#REF!+#REF!+#REF!+#REF!+#REF!+#REF!+#REF!+#REF!+'Well Template'!B8+#REF!+#REF!+#REF!+#REF!+#REF!+#REF!+#REF!+#REF!+#REF!+#REF!+#REF!+#REF! -> #REF! | C9: ='Summary Template'!AA185 -> #REF! | D9: =#REF!+#REF!+#REF!+#REF!+#REF!+#REF!+#REF!+#REF!+#REF!+#REF!+#REF!+#REF!+'Well Template'!H8+#REF!+#REF!+#REF!+#REF!+#REF!+#REF!+#REF!+#REF!+#REF!+#REF!+#REF!+#REF! -> #REF! | E9: ='Summary Template'!AA5 -> #REF! | F9: =+E9*6.2898 -> #REF! | G9: ='Summary Template'!AA76 -> #REF! | H9: ='Summary Template'!AA113 -> #REF! | I9: =#REF!+#REF!+#REF!+#REF!+#REF!+#REF!+#REF!+#REF!+#REF!+#REF!+#REF!+#REF!+'Well Template'!L8+#REF!+#REF!+#REF!+#REF!+#REF!+#REF!+#REF!+#REF!+#REF!+#REF!+#REF!+#REF! -> #REF! | J9: ='Summary Template'!AA40 -> #REF! | K9: ='Summary Template'!AA149 -> #REF! | L9: =#REF!+#REF!+#REF!+#REF!+#REF!+#REF!+#REF!+#REF!+#REF!+#REF!+#REF!+#REF!+'Well Template'!R8+#REF!+#REF!+#REF!+#REF!+#REF!+#REF!+#REF!+#REF!+#REF!+#REF!+#REF!+#REF! -> #REF! | M9: =#REF!+#REF!+#REF!+#REF!+#REF!+#REF!+#REF!+#REF!+#REF!+#REF!+#REF!+#REF!+'Well Template'!T7+#REF!+#REF!+#REF!+#REF!+#REF!+#REF!+#REF!+#REF!+#REF!+#REF!+#REF!+#REF! -> #REF! | N9: =#REF!+#REF!+#REF!+#REF!+#REF!+#REF!+#REF!+#REF!+#REF!+#REF!+#REF!+#REF!+'Well Template'!U8+#REF!+#REF!+#REF!+#REF!+#REF!+#REF!+#REF!+#REF!+#REF!+#REF!+#REF!+#REF! -> #REF! | O9: =#REF!+#REF!+#REF!+#REF!+#REF!+#REF!+#REF!+#REF!+#REF!+#REF!+#REF!+#REF!+'Well Template'!V8+#REF!+#REF!+#REF!+#REF!+#REF!+#REF!+#REF!+#REF!+#REF!+#REF!+#REF!+#REF! -> #REF!
A10: =+A9+1 -> 3 | B10: =#REF!+#REF!+#REF!+#REF!+#REF!+#REF!+#REF!+#REF!+#REF!+#REF!+#REF!+#REF!+'Well Template'!B9+#REF!+#REF!+#REF!+#REF!+#REF!+#REF!+#REF!+#REF!+#REF!+#REF!+#REF!+#REF! -> #REF! | C10: ='Summary Template'!AA186 -> #REF! | D10: =#REF!+#REF!+#REF!+#REF!+#REF!+#REF!+#REF!+#REF!+#REF!+#REF!+#REF!+#REF!+'Well Template'!H9+#REF!+#REF!+#REF!+#REF!+#REF!+#REF!+#REF!+#REF!+#REF!+#REF!+#REF!+#REF! -> #REF! | E10: ='Summary Template'!AA6 -> #REF! | F10: =+E10*6.2898 -> #REF! | G10: ='Summary Template'!AA77 -> #REF! | H10: ='Summary Template'!AA114 -> #REF! | I10: =#REF!+#REF!+#REF!+#REF!+#REF!+#REF!+#REF!+#REF!+#REF!+#REF!+#REF!+#REF!+'Well Template'!L9+#REF!+#REF!+#REF!+#REF!+#REF!+#REF!+#REF!+#REF!+#REF!+#REF!+#REF!+#REF! -> #REF! | J10: ='Summary Template'!AA41 -> #REF! | K10: ='Summary Template'!AA150 -> #REF! | L10: =#REF!+#REF!+#REF!+#REF!+#REF!+#REF!+#REF!+#REF!+#REF!+#REF!+#REF!+#REF!+'Well Template'!R9+#REF!+#REF!+#REF!+#REF!+#REF!+#REF!+#REF!+#REF!+#REF!+#REF!+#REF!+#REF! -> #REF! | M10: =#REF!+#REF!+#REF!+#REF!+#REF!+#REF!+#REF!+#REF!+#REF!+#REF!+#REF!+#REF!+'Well Template'!T9+#REF!+#REF!+#REF!+#REF!+#REF!+#REF!+#REF!+#REF!+#REF!+#REF!+#REF!+#REF! -> #REF! | N10: =#REF!+#REF!+#REF!+#REF!+#REF!+#REF!+#REF!+#REF!+#REF!+#REF!+#REF!+#REF!+'Well Template'!U9+#REF!+#REF!+#REF!+#REF!+#REF!+#REF!+#REF!+#REF!+#REF!+#REF!+#REF!+#REF! -> #REF! | O10: =#REF!+#REF!+#REF!+#REF!+#REF!+#REF!+#REF!+#REF!+#REF!+#REF!+#REF!+#REF!+'Well Template'!V9+#REF!+#REF!+#REF!+#REF!+#REF!+#REF!+#REF!+#REF!+#REF!+#REF!+#REF!+#REF! -> #REF!
A11: =+A10+1 -> 4 | B11: =#REF!+#REF!+#REF!+#REF!+#REF!+#REF!+#REF!+#REF!+#REF!+#REF!+#REF!+#REF!+'Well Template'!B10+#REF!+#REF!+#REF!+#REF!+#REF!+#REF!+#REF!+#REF!+#REF!+#REF!+#REF!+#REF! -> #REF! | C11: ='Summary Template'!AA187 -> #REF! | D11: =#REF!+#REF!+#REF!+#REF!+#REF!+#REF!+#REF!+#REF!+#REF!+#REF!+#REF!+#REF!+'Well Template'!H10+#REF!+#REF!+#REF!+#REF!+#REF!+#REF!+#REF!+#REF!+#REF!+#REF!+#REF!+#REF! -> #REF! | E11: ='Summary Template'!AA7 -> #REF! | F11: =+E11*6.2898 -> #REF! | G11: ='Summary Template'!AA78 -> #REF! | H11: ='Summary Template'!AA115 -> #REF! | I11: =#REF!+#REF!+#REF!+#REF!+#REF!+#REF!+#REF!+#REF!+#REF!+#REF!+#REF!+#REF!+'Well Template'!L10+#REF!+#REF!+#REF!+#REF!+#REF!+#REF!+#REF!+#REF!+#REF!+#REF!+#REF!+#REF! -> #REF! | J11: ='Summary Template'!AA42 -> #REF! | K11: ='Summary Template'!AA151 -> #REF! | L11: =#REF!+#REF!+#REF!+#REF!+#REF!+#REF!+#REF!+#REF!+#REF!+#REF!+#REF!+#REF!+'Well Template'!R10+#REF!+#REF!+#REF!+#REF!+#REF!+#REF!+#REF!+#REF!+#REF!+#REF!+#REF!+#REF! -> #REF! | M11: =#REF!+#REF!+#REF!+#REF!+#REF!+#REF!+#REF!+#REF!+#REF!+#REF!+#REF!+#REF!+'Well Template'!T10+#REF!+#REF!+#REF!+#REF!+#REF!+#REF!+#REF!+#REF!+#REF!+#REF!+#REF!+#REF! -> #REF! | N11: =#REF!+#REF!+#REF!+#REF!+#REF!+#REF!+#REF!+#REF!+#REF!+#REF!+#REF!+#REF!+'Well Template'!U10+#REF!+#REF!+#REF!+#REF!+#REF!+#REF!+#REF!+#REF!+#REF!+#REF!+#REF!+#REF! -> #REF! | O11: =#REF!+#REF!+#REF!+#REF!+#REF!+#REF!+#REF!+#REF!+#REF!+#REF!+#REF!+#REF!+'Well Template'!V10+#REF!+#REF!+#REF!+#REF!+#REF!+#REF!+#REF!+#REF!+#REF!+#REF!+#REF!+#REF! -> #REF!
A12: =+A11+1 -> 5 | B12: =#REF!+#REF!+#REF!+#REF!+#REF!+#REF!+#REF!+#REF!+#REF!+#REF!+#REF!+#REF!+'Well Template'!B11+#REF!+#REF!+#REF!+#REF!+#REF!+#REF!+#REF!+#REF!+#REF!+#REF!+#REF!+#REF! -> #REF! | C12: ='Summary Template'!AA188 -> #REF! | D12: =#REF!+#REF!+#REF!+#REF!+#REF!+#REF!+#REF!+#REF!+#REF!+#REF!+#REF!+#REF!+'Well Template'!H11+#REF!+#REF!+#REF!+#REF!+#REF!+#REF!+#REF!+#REF!+#REF!+#REF!+#REF!+#REF! -> #REF! | E12: ='Summary Template'!AA8 -> #REF! | F12: =+E12*6.2898 -> #REF! | G12: ='Summary Template'!AA79 -> #REF! | H12: ='Summary Template'!AA116 -> #REF! | I12: =#REF!+#REF!+#REF!+#REF!+#REF!+#REF!+#REF!+#REF!+#REF!+#REF!+#REF!+#REF!+'Well Template'!L11+#REF!+#REF!+#REF!+#REF!+#REF!+#REF!+#REF!+#REF!+#REF!+#REF!+#REF!+#REF! -> #REF! | J12: ='Summary Template'!AA43 -> #REF! | K12: ='Summary Template'!AA152 -> #REF! | L12: =#REF!+#REF!+#REF!+#REF!+#REF!+#REF!+#REF!+#REF!+#REF!+#REF!+#REF!+#REF!+'Well Template'!R11+#REF!+#REF!+#REF!+#REF!+#REF!+#REF!+#REF!+#REF!+#REF!+#REF!+#REF!+#REF! -> #REF! | M12: =#REF!+#REF!+#REF!+#REF!+#REF!+#REF!+#REF!+#REF!+#REF!+#REF!+#REF!+#REF!+'Well Template'!T11+#REF!+#REF!+#REF!+#REF!+#REF!+#REF!+#REF!+#REF!+#REF!+#REF!+#REF!+#REF! -> #REF! | N12: =#REF!+#REF!+#REF!+#REF!+#REF!+#REF!+#REF!+#REF!+#REF!+#REF!+#REF!+#REF!+'Well Template'!U11+#REF!+#REF!+#REF!+#REF!+#REF!+#REF!+#REF!+#REF!+#REF!+#REF!+#REF!+#REF! -> #REF! | O12: =#REF!+#REF!+#REF!+#REF!+#REF!+#REF!+#REF!+#REF!+#REF!+#REF!+#REF!+#REF!+'Well Template'!V11+#REF!+#REF!+#REF!+#REF!+#REF!+#REF!+#REF!+#REF!+#REF!+#REF!+#REF!+#REF! -> #REF!
A13: =+A12+1 -> 6 | B13: =#REF!+#REF!+#REF!+#REF!+#REF!+#REF!+#REF!+#REF!+#REF!+#REF!+#REF!+#REF!+'Well Template'!B12+#REF!+#REF!+#REF!+#REF!+#REF!+#REF!+#REF!+#REF!+#REF!+#REF!+#REF!+#REF! -> #REF! | C13: ='Summary Template'!AA189 -> #REF! | D13: =#REF!+#REF!+#REF!+#REF!+#REF!+#REF!+#REF!+#REF!+#REF!+#REF!+#REF!+#REF!+'Well Template'!H12+#REF!+#REF!+#REF!+#REF!+#REF!+#REF!+#REF!+#REF!+#REF!+#REF!+#REF!+#REF! -> #REF! | E13: ='Summary Template'!AA9 -> #REF! | F13: =+E13*6.2898 -> #REF! | G13: ='Summary Template'!AA80 -> #REF! | H13: ='Summary Template'!AA117 -> #REF! | I13: =#REF!+#REF!+#REF!+#REF!+#REF!+#REF!+#REF!+#REF!+#REF!+#REF!+#REF!+#REF!+'Well Template'!L12+#REF!+#REF!+#REF!+#REF!+#REF!+#REF!+#REF!+#REF!+#REF!+#REF!+#REF!+#REF! -> #REF! | J13: ='Summary Template'!AA44 -> #REF! | K13: ='Summary Template'!AA153 -> #REF! | L13: =#REF!+#REF!+#REF!+#REF!+#REF!+#REF!+#REF!+#REF!+#REF!+#REF!+#REF!+#REF!+'Well Template'!R12+#REF!+#REF!+#REF!+#REF!+#REF!+#REF!+#REF!+#REF!+#REF!+#REF!+#REF!+#REF! -> #REF! | M13: =#REF!+#REF!+#REF!+#REF!+#REF!+#REF!+#REF!+#REF!+#REF!+#REF!+#REF!+#REF!+'Well Template'!T12+#REF!+#REF!+#REF!+#REF!+#REF!+#REF!+#REF!+#REF!+#REF!+#REF!+#REF!+#REF! -> #REF! | N13: =#REF!+#REF!+#REF!+#REF!+#REF!+#REF!+#REF!+#REF!+#REF!+#REF!+#REF!+#REF!+'Well Template'!U12+#REF!+#REF!+#REF!+#REF!+#REF!+#REF!+#REF!+#REF!+#REF!+#REF!+#REF!+#REF! -> #REF! | O13: =#REF!+#REF!+#REF!+#REF!+#REF!+#REF!+#REF!+#REF!+#REF!+#REF!+#REF!+#REF!+'Well Template'!V12+#REF!+#REF!+#REF!+#REF!+#REF!+#REF!+#REF!+#REF!+#REF!+#REF!+#REF!+#REF! -> #REF!
A14: =+A13+1 -> 7 | B14: =#REF!+#REF!+#REF!+#REF!+#REF!+#REF!+#REF!+#REF!+#REF!+#REF!+#REF!+#REF!+'Well Template'!B13+#REF!+#REF!+#REF!+#REF!+#REF!+#REF!+#REF!+#REF!+#REF!+#REF!+#REF!+#REF! -> #REF! | C14: ='Summary Template'!AA190 -> #REF! | D14: =#REF!+#REF!+#REF!+#REF!+#REF!+#REF!+#REF!+#REF!+#REF!+#REF!+#REF!+#REF!+'Well Template'!H13+#REF!+#REF!+#REF!+#REF!+#REF!+#REF!+#REF!+#REF!+#REF!+#REF!+#REF!+#REF! -> #REF! | E14: ='Summary Template'!AA10 -> #REF! | F14: =+E14*6.2898 -> #REF! | G14: ='Summary Template'!AA81 -> #REF! | H14: ='Summary Template'!AA118 -> #REF! | I14: =#REF!+#REF!+#REF!+#REF!+#REF!+#REF!+#REF!+#REF!+#REF!+#REF!+#REF!+#REF!+'Well Template'!L13+#REF!+#REF!+#REF!+#REF!+#REF!+#REF!+#REF!+#REF!+#REF!+#REF!+#REF!+#REF! -> #REF! | J14: ='Summary Template'!AA45 -> #REF! | K14: ='Summary Template'!AA154 -> #REF! | L14: =#REF!+#REF!+#REF!+#REF!+#REF!+#REF!+#REF!+#REF!+#REF!+#REF!+#REF!+#REF!+'Well Template'!R13+#REF!+#REF!+#REF!+#REF!+#REF!+#REF!+#REF!+#REF!+#REF!+#REF!+#REF!+#REF! -> #REF! | M14: =#REF!+#REF!+#REF!+#REF!+#REF!+#REF!+#REF!+#REF!+#REF!+#REF!+#REF!+#REF!+'Well Template'!T13+#REF!+#REF!+#REF!+#REF!+#REF!+#REF!+#REF!+#REF!+#REF!+#REF!+#REF!+#REF! -> #REF! | N14: =#REF!+#REF!+#REF!+#REF!+#REF!+#REF!+#REF!+#REF!+#REF!+#REF!+#REF!+#REF!+'Well Template'!U13+#REF!+#REF!+#REF!+#REF!+#REF!+#REF!+#REF!+#REF!+#REF!+#REF!+#REF!+#REF! -> #REF! | O14: =#REF!+#REF!+#REF!+#REF!+#REF!+#REF!+#REF!+#REF!+#REF!+#REF!+#REF!+#REF!+'Well Template'!V13+#REF!+#REF!+#REF!+#REF!+#REF!+#REF!+#REF!+#REF!+#REF!+#REF!+#REF!+#REF! -> #REF!
A15: =+A14+1 -> 8 | B15: =#REF!+#REF!+#REF!+#REF!+#REF!+#REF!+#REF!+#REF!+#REF!+#REF!+#REF!+#REF!+'Well Template'!B14+#REF!+#REF!+#REF!+#REF!+#REF!+#REF!+#REF!+#REF!+#REF!+#REF!+#REF!+#REF! -> #REF! | C15: ='Summary Template'!AA191 -> #REF! | D15: =#REF!+#REF!+#REF!+#REF!+#REF!+#REF!+#REF!+#REF!+#REF!+#REF!+#REF!+#REF!+'Well Template'!H14+#REF!+#REF!+#REF!+#REF!+#REF!+#REF!+#REF!+#REF!+#REF!+#REF!+#REF!+#REF! -> #REF! | E15: ='Summary Template'!AA11 -> #REF! | F15: =+E15*6.2898 -> #REF! | G15: ='Summary Template'!AA82 -> #REF! | H15: ='Summary Template'!AA119 -> #REF! | I15: =#REF!+#REF!+#REF!+#REF!+#REF!+#REF!+#REF!+#REF!+#REF!+#REF!+#REF!+#REF!+'Well Template'!L14+#REF!+#REF!+#REF!+#REF!+#REF!+#REF!+#REF!+#REF!+#REF!+#REF!+#REF!+#REF! -> #REF! | J15: ='Summary Template'!AA46 -> #REF! | K15: ='Summary Template'!AA155 -> #REF! | L15: =#REF!+#REF!+#REF!+#REF!+#REF!+#REF!+#REF!+#REF!+#REF!+#REF!+#REF!+#REF!+'Well Template'!R14+#REF!+#REF!+#REF!+#REF!+#REF!+#REF!+#REF!+#REF!+#REF!+#REF!+#REF!+#REF! -> #REF! | M15: =#REF!+#REF!+#REF!+#REF!+#REF!+#REF!+#REF!+#REF!+#REF!+#REF!+#REF!+#REF!+'Well Template'!T13+#REF!+#REF!+#REF!+#REF!+#REF!+#REF!+#REF!+#REF!+#REF!+#REF!+#REF!+#REF! -> #REF! | N15: =#REF!+#REF!+#REF!+#REF!+#REF!+#REF!+#REF!+#REF!+#REF!+#REF!+#REF!+#REF!+'Well Template'!U14+#REF!+#REF!+#REF!+#REF!+#REF!+#REF!+#REF!+#REF!+#REF!+#REF!+#REF!+#REF! -> #REF! | O15: =#REF!+#REF!+#REF!+#REF!+#REF!+#REF!+#REF!+#REF!+#REF!+#REF!+#REF!+#REF!+'Well Template'!V14+#REF!+#REF!+#REF!+#REF!+#REF!+#REF!+#REF!+#REF!+#REF!+#REF!+#REF!+#REF! -> #REF!
A16: =+A15+1 -> 9 | B16: =#REF!+#REF!+#REF!+#REF!+#REF!+#REF!+#REF!+#REF!+#REF!+#REF!+#REF!+#REF!+'Well Template'!B15+#REF!+#REF!+#REF!+#REF!+#REF!+#REF!+#REF!+#REF!+#REF!+#REF!+#REF!+#REF! -> #REF! | C16: ='Summary Template'!AA192 -> #REF! | D16: =#REF!+#REF!+#REF!+#REF!+#REF!+#REF!+#REF!+#REF!+#REF!+#REF!+#REF!+#REF!+'Well Template'!H15+#REF!+#REF!+#REF!+#REF!+#REF!+#REF!+#REF!+#REF!+#REF!+#REF!+#REF!+#REF! -> #REF! | E16: ='Summary Template'!AA12 -> #REF! | F16: =+E16*6.2898 -> #REF! | G16: ='Summary Template'!AA83 -> #REF! | H16: ='Summary Template'!AA120 -> #REF! | I16: =#REF!+#REF!+#REF!+#REF!+#REF!+#REF!+#REF!+#REF!+#REF!+#REF!+#REF!+#REF!+'Well Template'!L15+#REF!+#REF!+#REF!+#REF!+#REF!+#REF!+#REF!+#REF!+#REF!+#REF!+#REF!+#REF! -> #REF! | J16: ='Summary Template'!AA47 -> #REF! | K16: ='Summary Template'!AA156 -> #REF! | L16: =#REF!+#REF!+#REF!+#REF!+#REF!+#REF!+#REF!+#REF!+#REF!+#REF!+#REF!+#REF!+'Well Template'!R15+#REF!+#REF!+#REF!+#REF!+#REF!+#REF!+#REF!+#REF!+#REF!+#REF!+#REF!+#REF! -> #REF! | M16: =#REF!+#REF!+#REF!+#REF!+#REF!+#REF!+#REF!+#REF!+#REF!+#REF!+#REF!+#REF!+'Well Template'!T15+#REF!+#REF!+#REF!+#REF!+#REF!+#REF!+#REF!+#REF!+#REF!+#REF!+#REF!+#REF! -> #REF! | N16: =#REF!+#REF!+#REF!+#REF!+#REF!+#REF!+#REF!+#REF!+#REF!+#REF!+#REF!+#REF!+'Well Template'!U15+#REF!+#REF!+#REF!+#REF!+#REF!+#REF!+#REF!+#REF!+#REF!+#REF!+#REF!+#REF! -> #REF! | O16: =#REF!+#REF!+#REF!+#REF!+#REF!+#REF!+#REF!+#REF!+#REF!+#REF!+#REF!+#REF!+'Well Template'!V15+#REF!+#REF!+#REF!+#REF!+#REF!+#REF!+#REF!+#REF!+#REF!+#REF!+#REF!+#REF! -> #REF!
A17: =+A16+1 -> 10 | B17: =#REF!+#REF!+#REF!+#REF!+#REF!+#REF!+#REF!+#REF!+#REF!+#REF!+#REF!+#REF!+'Well Template'!B16+#REF!+#REF!+#REF!+#REF!+#REF!+#REF!+#REF!+#REF!+#REF!+#REF!+#REF!+#REF! -> #REF! | C17: ='Summary Template'!AA193 -> #REF! | D17: =#REF!+#REF!+#REF!+#REF!+#REF!+#REF!+#REF!+#REF!+#REF!+#REF!+#REF!+#REF!+'Well Template'!H16+#REF!+#REF!+#REF!+#REF!+#REF!+#REF!+#REF!+#REF!+#REF!+#REF!+#REF!+#REF! -> #REF! | E17: ='Summary Template'!AA13 -> #REF! | F17: =+E17*6.2898 -> #REF! | G17: ='Summary Template'!AA84 -> #REF! | H17: ='Summary Template'!AA121 -> #REF! | I17: =#REF!+#REF!+#REF!+#REF!+#REF!+#REF!+#REF!+#REF!+#REF!+#REF!+#REF!+#REF!+'Well Template'!L16+#REF!+#REF!+#REF!+#REF!+#REF!+#REF!+#REF!+#REF!+#REF!+#REF!+#REF!+#REF! -> #REF! | J17: ='Summary Template'!AA48 -> #REF! | K17: ='Summary Template'!AA157 -> #REF! | L17: =#REF!+#REF!+#REF!+#REF!+#REF!+#REF!+#REF!+#REF!+#REF!+#REF!+#REF!+#REF!+'Well Template'!R16+#REF!+#REF!+#REF!+#REF!+#REF!+#REF!+#REF!+#REF!+#REF!+#REF!+#REF!+#REF! -> #REF! | M17: =#REF!+#REF!+#REF!+#REF!+#REF!+#REF!+#REF!+#REF!+#REF!+#REF!+#REF!+#REF!+'Well Template'!T16+#REF!+#REF!+#REF!+#REF!+#REF!+#REF!+#REF!+#REF!+#REF!+#REF!+#REF!+#REF! -> #REF! | N17: =#REF!+#REF!+#REF!+#REF!+#REF!+#REF!+#REF!+#REF!+#REF!+#REF!+#REF!+#REF!+'Well Template'!U16+#REF!+#REF!+#REF!+#REF!+#REF!+#REF!+#REF!+#REF!+#REF!+#REF!+#REF!+#REF! -> #REF! | O17: =#REF!+#REF!+#REF!+#REF!+#REF!+#REF!+#REF!+#REF!+#REF!+#REF!+#REF!+#REF!+'Well Template'!V16+#REF!+#REF!+#REF!+#REF!+#REF!+#REF!+#REF!+#REF!+#REF!+#REF!+#REF!+#REF! -> #REF!
A18: =+A17+1 -> 11 | B18: =#REF!+#REF!+#REF!+#REF!+#REF!+#REF!+#REF!+#REF!+#REF!+#REF!+#REF!+#REF!+'Well Template'!B17+#REF!+#REF!+#REF!+#REF!+#REF!+#REF!+#REF!+#REF!+#REF!+#REF!+#REF!+#REF! -> #REF! | C18: ='Summary Template'!AA194 -> #REF! | D18: =#REF!+#REF!+#REF!+#REF!+#REF!+#REF!+#REF!+#REF!+#REF!+#REF!+#REF!+#REF!+'Well Template'!H17+#REF!+#REF!+#REF!+#REF!+#REF!+#REF!+#REF!+#REF!+#REF!+#REF!+#REF!+#REF! -> #REF! | E18: ='Summary Template'!AA14 -> #REF! | F18: =+E18*6.2898 -> #REF! | G18: ='Summary Template'!AA85 -> #REF! | H18: ='Summary Template'!AA122 -> #REF! | I18: =#REF!+#REF!+#REF!+#REF!+#REF!+#REF!+#REF!+#REF!+#REF!+#REF!+#REF!+#REF!+'Well Template'!L17+#REF!+#REF!+#REF!+#REF!+#REF!+#REF!+#REF!+#REF!+#REF!+#REF!+#REF!+#REF! -> #REF! | J18: ='Summary Template'!AA49 -> #REF! | K18: ='Summary Template'!AA158 -> #REF! | L18: =#REF!+#REF!+#REF!+#REF!+#REF!+#REF!+#REF!+#REF!+#REF!+#REF!+#REF!+#REF!+'Well Template'!R17+#REF!+#REF!+#REF!+#REF!+#REF!+#REF!+#REF!+#REF!+#REF!+#REF!+#REF!+#REF! -> #REF! | M18: =#REF!+#REF!+#REF!+#REF!+#REF!+#REF!+#REF!+#REF!+#REF!+#REF!+#REF!+#REF!+'Well Template'!T17+#REF!+#REF!+#REF!+#REF!+#REF!+#REF!+#REF!+#REF!+#REF!+#REF!+#REF!+#REF! -> #REF! | N18: =#REF!+#REF!+#REF!+#REF!+#REF!+#REF!+#REF!+#REF!+#REF!+#REF!+#REF!+#REF!+'Well Template'!U17+#REF!+#REF!+#REF!+#REF!+#REF!+#REF!+#REF!+#REF!+#REF!+#REF!+#REF!+#REF! -> #REF! | O18: =#REF!+#REF!+#REF!+#REF!+#REF!+#REF!+#REF!+#REF!+#REF!+#REF!+#REF!+#REF!+'Well Template'!V17+#REF!+#REF!+#REF!+#REF!+#REF!+#REF!+#REF!+#REF!+#REF!+#REF!+#REF!+#REF! -> #REF!
A19: =+A18+1 -> 12 | B19: =#REF!+#REF!+#REF!+#REF!+#REF!+#REF!+#REF!+#REF!+#REF!+#REF!+#REF!+#REF!+'Well Template'!B18+#REF!+#REF!+#REF!+#REF!+#REF!+#REF!+#REF!+#REF!+#REF!+#REF!+#REF!+#REF! -> #REF! | C19: ='Summary Template'!AA195 -> #REF! | D19: =#REF!+#REF!+#REF!+#REF!+#REF!+#REF!+#REF!+#REF!+#REF!+#REF!+#REF!+#REF!+'Well Template'!H18+#REF!+#REF!+#REF!+#REF!+#REF!+#REF!+#REF!+#REF!+#REF!+#REF!+#REF!+#REF! -> #REF! | E19: ='Summary Template'!AA15 -> #REF! | F19: =+E19*6.2898 -> #REF! | G19: ='Summary Template'!AA86 -> #REF! | H19: ='Summary Template'!AA123 -> #REF! | I19: =#REF!+#REF!+#REF!+#REF!+#REF!+#REF!+#REF!+#REF!+#REF!+#REF!+#REF!+#REF!+'Well Template'!L18+#REF!+#REF!+#REF!+#REF!+#REF!+#REF!+#REF!+#REF!+#REF!+#REF!+#REF!+#REF! -> #REF! | J19: ='Summary Template'!AA50 -> #REF! | K19: ='Summary Template'!AA159 -> #REF! | L19: =#REF!+#REF!+#REF!+#REF!+#REF!+#REF!+#REF!+#REF!+#REF!+#REF!+#REF!+#REF!+'Well Template'!R18+#REF!+#REF!+#REF!+#REF!+#REF!+#REF!+#REF!+#REF!+#REF!+#REF!+#REF!+#REF! -> #REF! | M19: =#REF!+#REF!+#REF!+#REF!+#REF!+#REF!+#REF!+#REF!+#REF!+#REF!+#REF!+#REF!+'Well Template'!T18+#REF!+#REF!+#REF!+#REF!+#REF!+#REF!+#REF!+#REF!+#REF!+#REF!+#REF!+#REF! -> #REF! | N19: =#REF!+#REF!+#REF!+#REF!+#REF!+#REF!+#REF!+#REF!+#REF!+#REF!+#REF!+#REF!+'Well Template'!U18+#REF!+#REF!+#REF!+#REF!+#REF!+#REF!+#REF!+#REF!+#REF!+#REF!+#REF!+#REF! -> #REF! | O19: =#REF!+#REF!+#REF!+#REF!+#REF!+#REF!+#REF!+#REF!+#REF!+#REF!+#REF!+#REF!+'Well Template'!V18+#REF!+#REF!+#REF!+#REF!+#REF!+#REF!+#REF!+#REF!+#REF!+#REF!+#REF!+#REF! -> #REF!
A20: =+A19+1 -> 13 | B20: =#REF!+#REF!+#REF!+#REF!+#REF!+#REF!+#REF!+#REF!+#REF!+#REF!+#REF!+#REF!+'Well Template'!B19+#REF!+#REF!+#REF!+#REF!+#REF!+#REF!+#REF!+#REF!+#REF!+#REF!+#REF!+#REF! -> #REF! | C20: ='Summary Template'!AA196 -> #REF! | D20: =#REF!+#REF!+#REF!+#REF!+#REF!+#REF!+#REF!+#REF!+#REF!+#REF!+#REF!+#REF!+'Well Template'!H19+#REF!+#REF!+#REF!+#REF!+#REF!+#REF!+#REF!+#REF!+#REF!+#REF!+#REF!+#REF! -> #REF! | E20: ='Summary Template'!AA16 -> #REF! | F20: =+E20*6.2898 -> #REF! | G20: ='Summary Template'!AA87 -> #REF! | H20: ='Summary Template'!AA124 -> #REF! | I20: =#REF!+#REF!+#REF!+#REF!+#REF!+#REF!+#REF!+#REF!+#REF!+#REF!+#REF!+#REF!+'Well Template'!L19+#REF!+#REF!+#REF!+#REF!+#REF!+#REF!+#REF!+#REF!+#REF!+#REF!+#REF!+#REF! -> #REF! | J20: ='Summary Template'!AA51 -> #REF! | K20: ='Summary Template'!AA160 -> #REF! | L20: =#REF!+#REF!+#REF!+#REF!+#REF!+#REF!+#REF!+#REF!+#REF!+#REF!+#REF!+#REF!+'Well Template'!R19+#REF!+#REF!+#REF!+#REF!+#REF!+#REF!+#REF!+#REF!+#REF!+#REF!+#REF!+#REF! -> #REF! | M20: =#REF!+#REF!+#REF!+#REF!+#REF!+#REF!+#REF!+#REF!+#REF!+#REF!+#REF!+#REF!+'Well Template'!T19+#REF!+#REF!+#REF!+#REF!+#REF!+#REF!+#REF!+#REF!+#REF!+#REF!+#REF!+#REF! -> #REF! | N20: =#REF!+#REF!+#REF!+#REF!+#REF!+#REF!+#REF!+#REF!+#REF!+#REF!+#REF!+#REF!+'Well Template'!U19+#REF!+#REF!+#REF!+#REF!+#REF!+#REF!+#REF!+#REF!+#REF!+#REF!+#REF!+#REF! -> #REF! | O20: =#REF!+#REF!+#REF!+#REF!+#REF!+#REF!+#REF!+#REF!+#REF!+#REF!+#REF!+#REF!+'Well Template'!V19+#REF!+#REF!+#REF!+#REF!+#REF!+#REF!+#REF!+#REF!+#REF!+#REF!+#REF!+#REF! -> #REF!
A21: =+A20+1 -> 14 | B21: =#REF!+#REF!+#REF!+#REF!+#REF!+#REF!+#REF!+#REF!+#REF!+#REF!+#REF!+#REF!+'Well Template'!B20+#REF!+#REF!+#REF!+#REF!+#REF!+#REF!+#REF!+#REF!+#REF!+#REF!+#REF!+#REF! -> #REF! | C21: ='Summary Template'!AA197 -> #REF! | D21: =#REF!+#REF!+#REF!+#REF!+#REF!+#REF!+#REF!+#REF!+#REF!+#REF!+#REF!+#REF!+'Well Template'!H20+#REF!+#REF!+#REF!+#REF!+#REF!+#REF!+#REF!+#REF!+#REF!+#REF!+#REF!+#REF! -> #REF! | E21: ='Summary Template'!AA17 -> #REF! | F21: =+E21*6.2898 -> #REF! | G21: ='Summary Template'!AA88 -> #REF! | H21: ='Summary Template'!AA125 -> #REF! | I21: =#REF!+#REF!+#REF!+#REF!+#REF!+#REF!+#REF!+#REF!+#REF!+#REF!+#REF!+#REF!+'Well Template'!L20+#REF!+#REF!+#REF!+#REF!+#REF!+#REF!+#REF!+#REF!+#REF!+#REF!+#REF!+#REF! -> #REF! | J21: ='Summary Template'!AA52 -> #REF! | K21: ='Summary Template'!AA161 -> #REF! | L21: =#REF!+#REF!+#REF!+#REF!+#REF!+#REF!+#REF!+#REF!+#REF!+#REF!+#REF!+#REF!+'Well Template'!R20+#REF!+#REF!+#REF!+#REF!+#REF!+#REF!+#REF!+#REF!+#REF!+#REF!+#REF!+#REF! -> #REF! | M21: =#REF!+#REF!+#REF!+#REF!+#REF!+#REF!+#REF!+#REF!+#REF!+#REF!+#REF!+#REF!+'Well Template'!T20+#REF!+#REF!+#REF!+#REF!+#REF!+#REF!+#REF!+#REF!+#REF!+#REF!+#REF!+#REF! -> #REF! | N21: =#REF!+#REF!+#REF!+#REF!+#REF!+#REF!+#REF!+#REF!+#REF!+#REF!+#REF!+#REF!+'Well Template'!U20+#REF!+#REF!+#REF!+#REF!+#REF!+#REF!+#REF!+#REF!+#REF!+#REF!+#REF!+#REF! -> #REF! | O21: =#REF!+#REF!+#REF!+#REF!+#REF!+#REF!+#REF!+#REF!+#REF!+#REF!+#REF!+#REF!+'Well Template'!V20+#REF!+#REF!+#REF!+#REF!+#REF!+#REF!+#REF!+#REF!+#REF!+#REF!+#REF!+#REF! -> #REF!
A22: =+A21+1 -> 15 | B22: =#REF!+#REF!+#REF!+#REF!+#REF!+#REF!+#REF!+#REF!+#REF!+#REF!+#REF!+#REF!+'Well Template'!B21+#REF!+#REF!+#REF!+#REF!+#REF!+#REF!+#REF!+#REF!+#REF!+#REF!+#REF!+#REF! -> #REF! | C22: ='Summary Template'!AA198 -> #REF! | D22: =#REF!+#REF!+#REF!+#REF!+#REF!+#REF!+#REF!+#REF!+#REF!+#REF!+#REF!+#REF!+'Well Template'!H21+#REF!+#REF!+#REF!+#REF!+#REF!+#REF!+#REF!+#REF!+#REF!+#REF!+#REF!+#REF! -> #REF! | E22: ='Summary Template'!AA18 -> #REF! | F22: =+E22*6.2898 -> #REF! | G22: ='Summary Template'!AA89 -> #REF! | H22: ='Summary Template'!AA126 -> #REF! | I22: =#REF!+#REF!+#REF!+#REF!+#REF!+#REF!+#REF!+#REF!+#REF!+#REF!+#REF!+#REF!+'Well Template'!L21+#REF!+#REF!+#REF!+#REF!+#REF!+#REF!+#REF!+#REF!+#REF!+#REF!+#REF!+#REF! -> #REF! | J22: ='Summary Template'!AA53 -> #REF! | K22: ='Summary Template'!AA162 -> #REF! | L22: =#REF!+#REF!+#REF!+#REF!+#REF!+#REF!+#REF!+#REF!+#REF!+#REF!+#REF!+#REF!+'Well Template'!R21+#REF!+#REF!+#REF!+#REF!+#REF!+#REF!+#REF!+#REF!+#REF!+#REF!+#REF!+#REF! -> #REF! | M22: =#REF!+#REF!+#REF!+#REF!+#REF!+#REF!+#REF!+#REF!+#REF!+#REF!+#REF!+#REF!+'Well Template'!T21+#REF!+#REF!+#REF!+#REF!+#REF!+#REF!+#REF!+#REF!+#REF!+#REF!+#REF!+#REF! -> #REF! | N22: =#REF!+#REF!+#REF!+#REF!+#REF!+#REF!+#REF!+#REF!+#REF!+#REF!+#REF!+#REF!+'Well Template'!U21+#REF!+#REF!+#REF!+#REF!+#REF!+#REF!+#REF!+#REF!+#REF!+#REF!+#REF!+#REF! -> #REF! | O22: =#REF!+#REF!+#REF!+#REF!+#REF!+#REF!+#REF!+#REF!+#REF!+#REF!+#REF!+#REF!+'Well Template'!V21+#REF!+#REF!+#REF!+#REF!+#REF!+#REF!+#REF!+#REF!+#REF!+#REF!+#REF!+#REF! -> #REF!
A23: =+A22+1 -> 16 | B23: =#REF!+#REF!+#REF!+#REF!+#REF!+#REF!+#REF!+#REF!+#REF!+#REF!+#REF!+#REF!+'Well Template'!B22+#REF!+#REF!+#REF!+#REF!+#REF!+#REF!+#REF!+#REF!+#REF!+#REF!+#REF!+#REF! -> #REF! | C23: ='Summary Template'!AA199 -> #REF! | D23: =#REF!+#REF!+#REF!+#REF!+#REF!+#REF!+#REF!+#REF!+#REF!+#REF!+#REF!+#REF!+'Well Template'!H22+#REF!+#REF!+#REF!+#REF!+#REF!+#REF!+#REF!+#REF!+#REF!+#REF!+#REF!+#REF! -> #REF! | E23: ='Summary Template'!AA19 -> #REF! | F23: =+E23*6.2898 -> #REF! | G23: ='Summary Template'!AA90 -> #REF! | H23: ='Summary Template'!AA127 -> #REF! | I23: =#REF!+#REF!+#REF!+#REF!+#REF!+#REF!+#REF!+#REF!+#REF!+#REF!+#REF!+#REF!+'Well Template'!L22+#REF!+#REF!+#REF!+#REF!+#REF!+#REF!+#REF!+#REF!+#REF!+#REF!+#REF!+#REF! -> #REF! | J23: ='Summary Template'!AA54 -> #REF! | K23: ='Summary Template'!AA163 -> #REF! | L23: =#REF!+#REF!+#REF!+#REF!+#REF!+#REF!+#REF!+#REF!+#REF!+#REF!+#REF!+#REF!+'Well Template'!R22+#REF!+#REF!+#REF!+#REF!+#REF!+#REF!+#REF!+#REF!+#REF!+#REF!+#REF!+#REF! -> #REF! | M23: =#REF!+#REF!+#REF!+#REF!+#REF!+#REF!+#REF!+#REF!+#REF!+#REF!+#REF!+#REF!+'Well Template'!T22+#REF!+#REF!+#REF!+#REF!+#REF!+#REF!+#REF!+#REF!+#REF!+#REF!+#REF!+#REF! -> #REF! | N23: =#REF!+#REF!+#REF!+#REF!+#REF!+#REF!+#REF!+#REF!+#REF!+#REF!+#REF!+#REF!+'Well Template'!U22+#REF!+#REF!+#REF!+#REF!+#REF!+#REF!+#REF!+#REF!+#REF!+#REF!+#REF!+#REF! -> #REF! | O23: =#REF!+#REF!+#REF!+#REF!+#REF!+#REF!+#REF!+#REF!+#REF!+#REF!+#REF!+#REF!+'Well Template'!V22+#REF!+#REF!+#REF!+#REF!+#REF!+#REF!+#REF!+#REF!+#REF!+#REF!+#REF!+#REF! -> #REF!
A24: =+A23+1 -> 17 | B24: =#REF!+#REF!+#REF!+#REF!+#REF!+#REF!+#REF!+#REF!+#REF!+#REF!+#REF!+#REF!+'Well Template'!B23+#REF!+#REF!+#REF!+#REF!+#REF!+#REF!+#REF!+#REF!+#REF!+#REF!+#REF!+#REF! -> #REF! | C24: ='Summary Template'!AA200 -> #REF! | D24: =#REF!+#REF!+#REF!+#REF!+#REF!+#REF!+#REF!+#REF!+#REF!+#REF!+#REF!+#REF!+'Well Template'!H23+#REF!+#REF!+#REF!+#REF!+#REF!+#REF!+#REF!+#REF!+#REF!+#REF!+#REF!+#REF! -> #REF! | E24: ='Summary Template'!AA20 -> #REF! | F24: =+E24*6.2898 -> #REF! | G24: ='Summary Template'!AA91 -> #REF! | H24: ='Summary Template'!AA128 -> #REF! | I24: =#REF!+#REF!+#REF!+#REF!+#REF!+#REF!+#REF!+#REF!+#REF!+#REF!+#REF!+#REF!+'Well Template'!L23+#REF!+#REF!+#REF!+#REF!+#REF!+#REF!+#REF!+#REF!+#REF!+#REF!+#REF!+#REF! -> #REF! | J24: ='Summary Template'!AA55 -> #REF! | K24: ='Summary Template'!AA164 -> #REF! | L24: =#REF!+#REF!+#REF!+#REF!+#REF!+#REF!+#REF!+#REF!+#REF!+#REF!+#REF!+#REF!+'Well Template'!R23+#REF!+#REF!+#REF!+#REF!+#REF!+#REF!+#REF!+#REF!+#REF!+#REF!+#REF!+#REF! -> #REF! | M24: =#REF!+#REF!+#REF!+#REF!+#REF!+#REF!+#REF!+#REF!+#REF!+#REF!+#REF!+#REF!+'Well Template'!T23+#REF!+#REF!+#REF!+#REF!+#REF!+#REF!+#REF!+#REF!+#REF!+#REF!+#REF!+#REF! -> #REF! | N24: =#REF!+#REF!+#REF!+#REF!+#REF!+#REF!+#REF!+#REF!+#REF!+#REF!+#REF!+#REF!+'Well Template'!U23+#REF!+#REF!+#REF!+#REF!+#REF!+#REF!+#REF!+#REF!+#REF!+#REF!+#REF!+#REF! -> #REF! | O24: =#REF!+#REF!+#REF!+#REF!+#REF!+#REF!+#REF!+#REF!+#REF!+#REF!+#REF!+#REF!+'Well Template'!V23+#REF!+#REF!+#REF!+#REF!+#REF!+#REF!+#REF!+#REF!+#REF!+#REF!+#REF!+#REF! -> #REF!
A25: =+A24+1 -> 18 | B25: =#REF!+#REF!+#REF!+#REF!+#REF!+#REF!+#REF!+#REF!+#REF!+#REF!+#REF!+#REF!+'Well Template'!B24+#REF!+#REF!+#REF!+#REF!+#REF!+#REF!+#REF!+#REF!+#REF!+#REF!+#REF!+#REF! -> #REF! | C25: ='Summary Template'!AA201 -> #REF! | D25: =#REF!+#REF!+#REF!+#REF!+#REF!+#REF!+#REF!+#REF!+#REF!+#REF!+#REF!+#REF!+'Well Template'!H24+#REF!+#REF!+#REF!+#REF!+#REF!+#REF!+#REF!+#REF!+#REF!+#REF!+#REF!+#REF! -> #REF! | E25: ='Summary Template'!AA21 -> #REF! | F25: =+E25*6.2898 -> #REF! | G25: ='Summary Template'!AA92 -> #REF! | H25: ='Summary Template'!AA129 -> #REF! | I25: =#REF!+#REF!+#REF!+#REF!+#REF!+#REF!+#REF!+#REF!+#REF!+#REF!+#REF!+#REF!+'Well Template'!L24+#REF!+#REF!+#REF!+#REF!+#REF!+#REF!+#REF!+#REF!+#REF!+#REF!+#REF!+#REF! -> #REF! | J25: ='Summary Template'!AA56 -> #REF! | K25: ='Summary Template'!AA165 -> #REF! | L25: =#REF!+#REF!+#REF!+#REF!+#REF!+#REF!+#REF!+#REF!+#REF!+#REF!+#REF!+#REF!+'Well Template'!R24+#REF!+#REF!+#REF!+#REF!+#REF!+#REF!+#REF!+#REF!+#REF!+#REF!+#REF!+#REF! -> #REF! | M25: =#REF!+#REF!+#REF!+#REF!+#REF!+#REF!+#REF!+#REF!+#REF!+#REF!+#REF!+#REF!+'Well Template'!T24+#REF!+#REF!+#REF!+#REF!+#REF!+#REF!+#REF!+#REF!+#REF!+#REF!+#REF!+#REF! -> #REF! | N25: =#REF!+#REF!+#REF!+#REF!+#REF!+#REF!+#REF!+#REF!+#REF!+#REF!+#REF!+#REF!+'Well Template'!U24+#REF!+#REF!+#REF!+#REF!+#REF!+#REF!+#REF!+#REF!+#REF!+#REF!+#REF!+#REF! -> #REF! | O25: =#REF!+#REF!+#REF!+#REF!+#REF!+#REF!+#REF!+#REF!+#REF!+#REF!+#REF!+#REF!+'Well Template'!V24+#REF!+#REF!+#REF!+#REF!+#REF!+#REF!+#REF!+#REF!+#REF!+#REF!+#REF!+#REF! -> #REF!
A26: =+A25+1 -> 19 | B26: =#REF!+#REF!+#REF!+#REF!+#REF!+#REF!+#REF!+#REF!+#REF!+#REF!+#REF!+#REF!+'Well Template'!B25+#REF!+#REF!+#REF!+#REF!+#REF!+#REF!+#REF!+#REF!+#REF!+#REF!+#REF!+#REF! -> #REF! | C26: ='Summary Template'!AA202 -> #REF! | D26: =#REF!+#REF!+#REF!+#REF!+#REF!+#REF!+#REF!+#REF!+#REF!+#REF!+#REF!+#REF!+'Well Template'!H25+#REF!+#REF!+#REF!+#REF!+#REF!+#REF!+#REF!+#REF!+#REF!+#REF!+#REF!+#REF! -> #REF! | E26: ='Summary Template'!AA22 -> #REF! | F26: =+E26*6.2898 -> #REF! | G26: ='Summary Template'!AA93 -> #REF! | H26: ='Summary Template'!AA130 -> #REF! | I26: =#REF!+#REF!+#REF!+#REF!+#REF!+#REF!+#REF!+#REF!+#REF!+#REF!+#REF!+#REF!+'Well Template'!L25+#REF!+#REF!+#REF!+#REF!+#REF!+#REF!+#REF!+#REF!+#REF!+#REF!+#REF!+#REF! -> #REF! | J26: ='Summary Template'!AA57 -> #REF! | K26: ='Summary Template'!AA166 -> #REF! | L26: =#REF!+#REF!+#REF!+#REF!+#REF!+#REF!+#REF!+#REF!+#REF!+#REF!+#REF!+#REF!+'Well Template'!R25+#REF!+#REF!+#REF!+#REF!+#REF!+#REF!+#REF!+#REF!+#REF!+#REF!+#REF!+#REF! -> #REF! | M26: =#REF!+#REF!+#REF!+#REF!+#REF!+#REF!+#REF!+#REF!+#REF!+#REF!+#REF!+#REF!+'Well Template'!T25+#REF!+#REF!+#REF!+#REF!+#REF!+#REF!+#REF!+#REF!+#REF!+#REF!+#REF!+#REF! -> #REF! | N26: =#REF!+#REF!+#REF!+#REF!+#REF!+#REF!+#REF!+#REF!+#REF!+#REF!+#REF!+#REF!+'Well Template'!U25+#REF!+#REF!+#REF!+#REF!+#REF!+#REF!+#REF!+#REF!+#REF!+#REF!+#REF!+#REF! -> #REF! | O26: =#REF!+#REF!+#REF!+#REF!+#REF!+#REF!+#REF!+#REF!+#REF!+#REF!+#REF!+#REF!+'Well Template'!V25+#REF!+#REF!+#REF!+#REF!+#REF!+#REF!+#REF!+#REF!+#REF!+#REF!+#REF!+#REF! -> #REF!
A27: =+A26+1 -> 20 | B27: =#REF!+#REF!+#REF!+#REF!+#REF!+#REF!+#REF!+#REF!+#REF!+#REF!+#REF!+#REF!+'Well Template'!B26+#REF!+#REF!+#REF!+#REF!+#REF!+#REF!+#REF!+#REF!+#REF!+#REF!+#REF!+#REF! -> #REF! | C27: ='Summary Template'!AA203 -> #REF! | D27: =#REF!+#REF!+#REF!+#REF!+#REF!+#REF!+#REF!+#REF!+#REF!+#REF!+#REF!+#REF!+'Well Template'!H26+#REF!+#REF!+#REF!+#REF!+#REF!+#REF!+#REF!+#REF!+#REF!+#REF!+#REF!+#REF! -> #REF! | E27: ='Summary Template'!AA23 -> #REF! | F27: =+E27*6.2898 -> #REF! | G27: ='Summary Template'!AA94 -> #REF! | H27: ='Summary Template'!AA131 -> #REF! | I27: =#REF!+#REF!+#REF!+#REF!+#REF!+#REF!+#REF!+#REF!+#REF!+#REF!+#REF!+#REF!+'Well Template'!L26+#REF!+#REF!+#REF!+#REF!+#REF!+#REF!+#REF!+#REF!+#REF!+#REF!+#REF!+#REF! -> #REF! | J27: ='Summary Template'!AA58 -> #REF! | K27: ='Summary Template'!AA167 -> #REF! | L27: =#REF!+#REF!+#REF!+#REF!+#REF!+#REF!+#REF!+#REF!+#REF!+#REF!+#REF!+#REF!+'Well Template'!R26+#REF!+#REF!+#REF!+#REF!+#REF!+#REF!+#REF!+#REF!+#REF!+#REF!+#REF!+#REF! -> #REF! | M27: =#REF!+#REF!+#REF!+#REF!+#REF!+#REF!+#REF!+#REF!+#REF!+#REF!+#REF!+#REF!+'Well Template'!T26+#REF!+#REF!+#REF!+#REF!+#REF!+#REF!+#REF!+#REF!+#REF!+#REF!+#REF!+#REF! -> #REF! | N27: =#REF!+#REF!+#REF!+#REF!+#REF!+#REF!+#REF!+#REF!+#REF!+#REF!+#REF!+#REF!+'Well Template'!U26+#REF!+#REF!+#REF!+#REF!+#REF!+#REF!+#REF!+#REF!+#REF!+#REF!+#REF!+#REF! -> #REF! | O27: =#REF!+#REF!+#REF!+#REF!+#REF!+#REF!+#REF!+#REF!+#REF!+#REF!+#REF!+#REF!+'Well Template'!V26+#REF!+#REF!+#REF!+#REF!+#REF!+#REF!+#REF!+#REF!+#REF!+#REF!+#REF!+#REF! -> #REF!
... A38: =+A37+1 -> 31 | B38: =#REF!+#REF!+#REF!+#REF!+#REF!+#REF!+#REF!+#REF!+#REF!+#REF!+#REF!+#REF!+'Well Template'!B37+#REF!+#REF!+#REF!+#REF!+#REF!+#REF!+#REF!+#REF!+#REF!+#REF!+#REF!+#REF! -> #REF! | C38: ='Summary Template'!AA214 -> #REF! | D38: =#REF!+#REF!+#REF!+#REF!+#REF!+#REF!+#REF!+#REF!+#REF!+#REF!+#REF!+#REF!+'Well Template'!H37+#REF!+#REF!+#REF!+#REF!+#REF!+#REF!+#REF!+#REF!+#REF!+#REF!+#REF!+#REF! -> #REF! | E38: ='Summary Template'!AA34 -> #REF! | F38: =+E38*6.2898 -> #REF! | G38: ='Summary Template'!AA105 -> #REF! | H38: ='Summary Template'!AA142 -> #REF! | I38: =#REF!+#REF!+#REF!+#REF!+#REF!+#REF!+#REF!+#REF!+#REF!+#REF!+#REF!+#REF!+'Well Template'!L37+#REF!+#REF!+#REF!+#REF!+#REF!+#REF!+#REF!+#REF!+#REF!+#REF!+#REF!+#REF! -> #REF! | J38: ='Summary Template'!AA69 -> #REF! | K38: ='Summary Template'!AA178 -> #REF! | L38: =#REF!+#REF!+#REF!+#REF!+#REF!+#REF!+#REF!+#REF!+#REF!+#REF!+#REF!+#REF!+'Well Template'!R37+#REF!+#REF!+#REF!+#REF!+#REF!+#REF!+#REF!+#REF!+#REF!+#REF!+#REF!+#REF! -> #REF! | M38: =#REF!+#REF!+#REF!+#REF!+#REF!+#REF!+#REF!+#REF!+#REF!+#REF!+#REF!+#REF!+'Well Template'!T37+#REF!+#REF!+#REF!+#REF!+#REF!+#REF!+#REF!+#REF!+#REF!+#REF!+#REF!+#REF! -> #REF! | N38: =#REF!+#REF!+#REF!+#REF!+#REF!+#REF!+#REF!+#REF!+#REF!+#REF!+#REF!+#REF!+'Well Template'!U37+#REF!+#REF!+#REF!+#REF!+#REF!+#REF!+#REF!+#REF!+#REF!+#REF!+#REF!+#REF! -> #REF! | O38: =#REF!+#REF!+#REF!+#REF!+#REF!+#REF!+#REF!+#REF!+#REF!+#REF!+#REF!+#REF!+'Well Template'!V37+#REF!+#REF!+#REF!+#REF!+#REF!+#REF!+#REF!+#REF!+#REF!+#REF!+#REF!+#REF! -> #REF!
A39: TOTAL | B39: =SUM(B8:B38) -> #REF! | C39: =SUM(C8:C38) -> #REF! | D39: =SUM(D8:D38) -> #REF! | E39: =SUM(E8:E38) -> #REF! | F39: =SUM(F8:F38) -> #REF! | G39: =SUM(G8:G38) -> #REF! | H39: =SUM(H8:H38) -> #REF! | I39: =SUM(I8:I38) -> #REF! | ... O39: =SUM(O8:O38) -> #REF!
C41: bbls | D41: =+D39*6.2898 -> #REF!

Sheet Well Template
H1: Total # of Joints: | Q1: # Jts after No-turn: | AD1: Location:
AD2: BATTERY
H3: Pump Make and Size: | Q3: Zone/Depth: | AD3: Month/Year:
A5: Date | B5: Hours | C5: Hours | D5: Reason for | E5: Total | F5: Sand | G5: Tank Gauge | H5: Prod | I5: Net Oil | J5: Net Sand | K5: Net Water | L5: Recycle | M5: Shipments | S5: Ticket # | T5: Fluid Out | U5: Fluid In | V5: Foam Loss | W5: Pressure | Y5: Propane | Z5: Tank Temp | AA5: Fluid Level | AB5: Pump | AD5: psi | AE5: Comments | AF5: Operators Initials | AH5: Tank 1 | AN5: Tank 2
B6: On | C6: Down | D6: Downtime | E6: BS&W | F6: % | H6: m3 | I6: m3 | J6: m3 | K6: m3 | L6: m3 | M6: Gross Vol | N6: BS&W | O6: Net Oil (m3) | P6: Water (m3) | Q6: Water Loads | R6: Sand (m3) | T6: m3 | U6: m3 | V6: m3 | W6: Tbg (kPa) | X6: Csg (kPa) | Y6: (%full) | Z6: #1 | AA6: (JTF) | AB6: (RPM) | AC6: Efficiency | AD6: Hyd | AG6: Tank Gauges Total | AH6: Tank LVL | AI6: 3' | AJ6: 5' | AK6: 7' | AL6: 9' | AM6: 12' | AN6: Tank LVL | AO6: 3' | AP6: 5' | AQ6: 7' | AR6: 9' | AS6: 12'
A7: 1
A8: 2
A9: 3
A10: 4
A11: 5
A12: 6
A13: 7
A14: 8
A15: 9
A16: 10
A17: 11
A18: 12
... A37: 31
A38: Cum
B40: Initial Tank Gauge= | F40: bbls
D41: Oil = | F41: bbls/cd
D42: Water = | F42: bbls/ad
D43: Sand =
D44: Total =

Sheet Second Well Template
A1: Date | B1: Fluid Type | C1: Volume (m3) | D1: Ticket | E1: Location: From | F1: Location: To | G1: Comments | M1: Day | N1: Third Party In | O1: Ticket Number | P1: Company | Q1: Total for that day | R1: meter | T1: Fluid in Disposal Tanks | X1: Trans pump numbers
T2: Inlet Tk | U2: Settling Tk | V2: Suction Tk | X2: c15-4 | Y2: C5-4 | Z2: c10-4 | AA2: C12-4 | AB2: hauled | AC2: total
A3: 1 | M3: 1 | Q3: =SUM(R3-R2) -> 0 | AC3: =SUM(X3:AB3) -> 0
A4: 2 | M4: 2 | Q4: =SUM(R4-R3) -> 0 | AC4: =SUM(X4:AB4) -> 0
A5: 3 | M5: 3 | Q5: =SUM(R5-R4) -> 0 | AC5: =SUM(X5:AB5) -> 0
A6: 4 | M6: 4 | Q6: =SUM(R6-R5) -> 0 | AC6: =SUM(X6:AB6) -> 0
A7: 5 | M7: 5 | Q7: =SUM(R7-R6) -> 0 | AC7: =SUM(X7:AB7) -> 0
A8: 6 | M8: 6 | Q8: =SUM(R8-R7) -> 0 | AC8: =SUM(X8:AB8) -> 0
A9: 7 | M9: 7 | Q9: =SUM(R9-R8) -> 0 | AC9: =SUM(X9:AB9) -> 0
A10: 8 | M10: 8 | Q10: =SUM(R10-R9) -> 0 | AC10: =SUM(X10:AB10) -> 0
A11: 9 | M11: 9 | Q11: =SUM(R11-R10) -> 0 | AC11: =SUM(X11:AB11) -> 0
A12: 10 | M12: 10 | Q12: =SUM(R12-R11) -> 0 | AC12: =SUM(X12:AB12) -> 0
A13: 11 | M13: 11 | Q13: =SUM(R13-R12) -> 0 | AC13: =SUM(X13:AB13) -> 0
A14: 12 | M14: 12 | Q14: =SUM(R14-R13) -> 0 | AC14: =SUM(X14:AB14) -> 0
... A26: 24 | M26: 24 | Q26: =SUM(R26-R25) -> 0 | AC26: =SUM(X26:AB26) -> 0
A27: 25 | M27: 25 | Q27: =SUM(R28-R26) -> 0 | AC27: =SUM(X27:AB27) -> 0
A28: 26 | M28: 26 | Q28: =SUM(R29-R28) -> 0 | AC28: =SUM(X28:AB28) -> 0
A29: 27 | M29: 27 | Q29: =SUM(R30-R29) -> 0 | AC29: =SUM(X29:AB29) -> 0
A30: 28 | M30: 28 | Q30: =SUM(R31-R30) -> 0 | AC30: =SUM(X30:AB30) -> 0
A31: 29 | M31: 29 | Q31: =SUM(R32-R31) -> 0 | AC31: =SUM(X31:AB31) -> 0
A32: 30 | M32: 30 | Q32: =SUM(R33-R32) -> 0 | AC32: =SUM(X32:AB32) -> 0
A33: 31 | M33: 31 | Q33: =SUM(R34-R33) -> 0 | AC33: =SUM(X33:AB33) -> 0
Q34: =(R34-R33) -> #REF! | R34: =(R34-R33) -> #REF! | X34: =SUM(X3:X33) -> 0 | Y34: =SUM(Y3:Y33) -> 0 | Z34: =SUM(Z3:Z33) -> 0 | AA34: =SUM(AA3:AA33) -> 0 | AB34: =SUM(AB3:AB33) -> 0 | AC34: =SUM(AC3:AC33) -> 0
N35: =SUM(N3:N33) -> 0
A36: Total | B36: H20 | C36: =SUM(C3:C35) -> 0

Sheet Summary Template
B2: NET OIL
A3: Date | B3: =#REF! -> #REF! | C3: =#REF! -> #REF! | D3: =#REF! -> #REF! | E3: =#REF! -> #REF! | F3: =#REF! -> #REF! | G3: =#REF! -> #REF! | H3: =#REF! -> #REF! | I3: =#REF! -> #REF! | ... M3: =#REF! -> #REF! | N3: ='Well Template'!AE1 -> 0 | O3: =#REF! -> #REF! | P3: =#REF! -> #REF! | Q3: =#REF! -> #REF! | R3: =#REF! -> #REF! | S3: =#REF! -> #REF! | T3: =#REF! -> #REF! | U3: =#REF! -> #REF! | V3: =#REF! -> #REF! | ... Z3: =#REF! -> #REF! | AA3: TOTAL
A4: 1 | B4: =#REF! -> #REF! | C4: =+#REF! -> #REF! | D4: =+#REF! -> #REF! | E4: =+#REF! -> #REF! | F4: =+#REF! -> #REF! | G4: =+#REF! -> #REF! | H4: =+#REF! -> #REF! | I4: =+#REF! -> #REF! | J4: =+#REF! -> #REF! | ... M4: =+#REF! -> #REF! | N4: =+'Well Template'!$I7 | O4: =+#REF! -> #REF! | P4: =+#REF! -> #REF! | Q4: =+#REF! -> #REF! | R4: =+#REF! -> #REF! | S4: =+#REF! -> #REF! | T4: =+#REF! -> #REF! | U4: =+#REF! -> #REF! | V4: =+#REF! -> #REF! | ... Z4: =+#REF! -> #REF! | AA4: =SUM(B4:Z4) -> #REF!
A5: =+A4+1 -> 2 | B5: =#REF! -> #REF! | C5: =+#REF! -> #REF! | D5: =+#REF! -> #REF! | E5: =+#REF! -> #REF! | F5: =+#REF! -> #REF! | G5: =+#REF! -> #REF! | H5: =+#REF! -> #REF! | I5: =+#REF! -> #REF! | J5: =+#REF! -> #REF! | ... M5: =+#REF! -> #REF! | N5: =+'Well Template'!$I8 | O5: =+#REF! -> #REF! | P5: =+#REF! -> #REF! | Q5: =+#REF! -> #REF! | R5: =+#REF! -> #REF! | S5: =+#REF! -> #REF! | T5: =+#REF! -> #REF! | U5: =+#REF! -> #REF! | V5: =+#REF! -> #REF! | ... Z5: =+#REF! -> #REF! | AA5: =SUM(B5:Z5) -> #REF!
A6: =+A5+1 -> 3 | B6: =#REF! -> #REF! | C6: =+#REF! -> #REF! | D6: =+#REF! -> #REF! | E6: =+#REF! -> #REF! | F6: =+#REF! -> #REF! | G6: =+#REF! -> #REF! | H6: =+#REF! -> #REF! | I6: =+#REF! -> #REF! | J6: =+#REF! -> #REF! | ... M6: =+#REF! -> #REF! | N6: =+'Well Template'!$I9 | O6: =+#REF! -> #REF! | P6: =+#REF! -> #REF! | Q6: =+#REF! -> #REF! | R6: =+#REF! -> #REF! | S6: =+#REF! -> #REF! | T6: =+#REF! -> #REF! | U6: =+#REF! -> #REF! | V6: =+#REF! -> #REF! | ... Z6: =+#REF! -> #REF! | AA6: =SUM(B6:Z6) -> #REF!
A7: =+A6+1 -> 4 | B7: =#REF! -> #REF! | C7: =+#REF! -> #REF! | D7: =+#REF! -> #REF! | E7: =+#REF! -> #REF! | F7: =+#REF! -> #REF! | G7: =+#REF! -> #REF! | H7: =+#REF! -> #REF! | I7: =+#REF! -> #REF! | J7: =+#REF! -> #REF! | ... M7: =+#REF! -> #REF! | N7: =+'Well Template'!$I10 | O7: =+#REF! -> #REF! | P7: =+#REF! -> #REF! | Q7: =+#REF! -> #REF! | R7: =+#REF! -> #REF! | S7: =+#REF! -> #REF! | T7: =+#REF! -> #REF! | U7: =+#REF! -> #REF! | V7: =+#REF! -> #REF! | ... Z7: =+#REF! -> #REF! | AA7: =SUM(B7:Z7) -> #REF!
A8: =+A7+1 -> 5 | B8: =#REF! -> #REF! | C8: =+#REF! -> #REF! | D8: =+#REF! -> #REF! | E8: =+#REF! -> #REF! | F8: =+#REF! -> #REF! | G8: =+#REF! -> #REF! | H8: =+#REF! -> #REF! | I8: =+#REF! -> #REF! | J8: =+#REF! -> #REF! | ... M8: =+#REF! -> #REF! | N8: =+'Well Template'!$I11 | O8: =+#REF! -> #REF! | P8: =+#REF! -> #REF! | Q8: =+#REF! -> #REF! | R8: =+#REF! -> #REF! | S8: =+#REF! -> #REF! | T8: =+#REF! -> #REF! | U8: =+#REF! -> #REF! | V8: =+#REF! -> #REF! | ... Z8: =+#REF! -> #REF! | AA8: =SUM(B8:Z8) -> #REF!
A9: =+A8+1 -> 6 | B9: =#REF! -> #REF! | C9: =+#REF! -> #REF! | D9: =+#REF! -> #REF! | E9: =+#REF! -> #REF! | F9: =+#REF! -> #REF! | G9: =+#REF! -> #REF! | H9: =+#REF! -> #REF! | I9: =+#REF! -> #REF! | J9: =+#REF! -> #REF! | ... M9: =+#REF! -> #REF! | N9: =+'Well Template'!$I12 | O9: =+#REF! -> #REF! | P9: =+#REF! -> #REF! | Q9: =+#REF! -> #REF! | R9: =+#REF! -> #REF! | S9: =+#REF! -> #REF! | T9: =+#REF! -> #REF! | U9: =+#REF! -> #REF! | V9: =+#REF! -> #REF! | ... Z9: =+#REF! -> #REF! | AA9: =SUM(B9:Z9) -> #REF!
A10: =+A9+1 -> 7 | B10: =#REF! -> #REF! | C10: =+#REF! -> #REF! | D10: =+#REF! -> #REF! | E10: =+#REF! -> #REF! | F10: =+#REF! -> #REF! | G10: =+#REF! -> #REF! | H10: =+#REF! -> #REF! | I10: =+#REF! -> #REF! | J10: =+#REF! -> #REF! | ... M10: =+#REF! -> #REF! | N10: =+'Well Template'!$I13 | O10: =+#REF! -> #REF! | P10: =+#REF! -> #REF! | Q10: =+#REF! -> #REF! | R10: =+#REF! -> #REF! | S10: =+#REF! -> #REF! | T10: =+#REF! -> #REF! | U10: =+#REF! -> #REF! | V10: =+#REF! -> #REF! | ... Z10: =+#REF! -> #REF! | AA10: =SUM(B10:Z10) -> #REF!
A11: 8 | B11: =#REF! -> #REF! | C11: =+#REF! -> #REF! | D11: =+#REF! -> #REF! | E11: =+#REF! -> #REF! | F11: =+#REF! -> #REF! | G11: =+#REF! -> #REF! | H11: =+#REF! -> #REF! | I11: =+#REF! -> #REF! | J11: =+#REF! -> #REF! | ... M11: =+#REF! -> #REF! | N11: =+'Well Template'!$I14 | O11: =+#REF! -> #REF! | P11: =+#REF! -> #REF! | Q11: =+#REF! -> #REF! | R11: =+#REF! -> #REF! | S11: =+#REF! -> #REF! | T11: =+#REF! -> #REF! | U11: =+#REF! -> #REF! | V11: =+#REF! -> #REF! | ... Z11: =+#REF! -> #REF! | AA11: =SUM(B11:Z11) -> #REF!
A12: =+A11+1 -> 9 | B12: =#REF! -> #REF! | C12: =+#REF! -> #REF! | D12: =+#REF! -> #REF! | E12: =+#REF! -> #REF! | F12: =+#REF! -> #REF! | G12: =+#REF! -> #REF! | H12: =+#REF! -> #REF! | I12: =+#REF! -> #REF! | J12: =+#REF! -> #REF! | ... M12: =+#REF! -> #REF! | N12: =+'Well Template'!$I15 | O12: =+#REF! -> #REF! | P12: =+#REF! -> #REF! | Q12: =+#REF! -> #REF! | R12: =+#REF! -> #REF! | S12: =+#REF! -> #REF! | T12: =+#REF! -> #REF! | U12: =+#REF! -> #REF! | V12: =+#REF! -> #REF! | ... Z12: =+#REF! -> #REF! | AA12: =SUM(B12:Z12) -> #REF!
A13: =+A12+1 -> 10 | B13: =#REF! -> #REF! | C13: =+#REF! -> #REF! | D13: =+#REF! -> #REF! | E13: =+#REF! -> #REF! | F13: =+#REF! -> #REF! | G13: =+#REF! -> #REF! | H13: =+#REF! -> #REF! | I13: =+#REF! -> #REF! | J13: =+#REF! -> #REF! | ... M13: =+#REF! -> #REF! | N13: =+'Well Template'!$I16 | O13: =+#REF! -> #REF! | P13: =+#REF! -> #REF! | Q13: =+#REF! -> #REF! | R13: =+#REF! -> #REF! | S13: =+#REF! -> #REF! | T13: =+#REF! -> #REF! | U13: =+#REF! -> #REF! | V13: =+#REF! -> #REF! | ... Z13: =+#REF! -> #REF! | AA13: =SUM(B13:Z13) -> #REF!
A14: =+A13+1 -> 11 | B14: =#REF! -> #REF! | C14: =+#REF! -> #REF! | D14: =+#REF! -> #REF! | E14: =+#REF! -> #REF! | F14: =+#REF! -> #REF! | G14: =+#REF! -> #REF! | H14: =+#REF! -> #REF! | I14: =+#REF! -> #REF! | J14: =+#REF! -> #REF! | ... M14: =+#REF! -> #REF! | N14: =+'Well Template'!$I17 | O14: =+#REF! -> #REF! | P14: =+#REF! -> #REF! | Q14: =+#REF! -> #REF! | R14: =+#REF! -> #REF! | S14: =+#REF! -> #REF! | T14: =+#REF! -> #REF! | U14: =+#REF! -> #REF! | V14: =+#REF! -> #REF! | ... Z14: =+#REF! -> #REF! | AA14: =SUM(B14:Z14) -> #REF!
A15: =+A14+1 -> 12 | B15: =#REF! -> #REF! | C15: =+#REF! -> #REF! | D15: =+#REF! -> #REF! | E15: =+#REF! -> #REF! | F15: =+#REF! -> #REF! | G15: =+#REF! -> #REF! | H15: =+#REF! -> #REF! | I15: =+#REF! -> #REF! | J15: =+#REF! -> #REF! | ... M15: =+#REF! -> #REF! | N15: =+'Well Template'!$I18 | O15: =+#REF! -> #REF! | P15: =+#REF! -> #REF! | Q15: =+#REF! -> #REF! | R15: =+#REF! -> #REF! | S15: =+#REF! -> #REF! | T15: =+#REF! -> #REF! | U15: =+#REF! -> #REF! | V15: =+#REF! -> #REF! | ... Z15: =+#REF! -> #REF! | AA15: =SUM(B15:Z15) -> #REF!
A16: =+A15+1 -> 13 | B16: =#REF! -> #REF! | C16: =+#REF! -> #REF! | D16: =+#REF! -> #REF! | E16: =+#REF! -> #REF! | F16: =+#REF! -> #REF! | G16: =+#REF! -> #REF! | H16: =+#REF! -> #REF! | I16: =+#REF! -> #REF! | J16: =+#REF! -> #REF! | ... M16: =+#REF! -> #REF! | N16: =+'Well Template'!$I19 | O16: =+#REF! -> #REF! | P16: =+#REF! -> #REF! | Q16: =+#REF! -> #REF! | R16: =+#REF! -> #REF! | S16: =+#REF! -> #REF! | T16: =+#REF! -> #REF! | U16: =+#REF! -> #REF! | V16: =+#REF! -> #REF! | ... Z16: =+#REF! -> #REF! | AA16: =SUM(B16:Z16) -> #REF!
A17: =+A16+1 -> 14 | B17: =#REF! -> #REF! | C17: =+#REF! -> #REF! | D17: =+#REF! -> #REF! | E17: =+#REF! -> #REF! | F17: =+#REF! -> #REF! | G17: =+#REF! -> #REF! | H17: =+#REF! -> #REF! | I17: =+#REF! -> #REF! | J17: =+#REF! -> #REF! | ... M17: =+#REF! -> #REF! | N17: =+'Well Template'!$I20 | O17: =+#REF! -> #REF! | P17: =+#REF! -> #REF! | Q17: =+#REF! -> #REF! | R17: =+#REF! -> #REF! | S17: =+#REF! -> #REF! | T17: =+#REF! -> #REF! | U17: =+#REF! -> #REF! | V17: =+#REF! -> #REF! | ... Z17: =+#REF! -> #REF! | AA17: =SUM(B17:Z17) -> #REF!
A18: =+A17+1 -> 15 | B18: =#REF! -> #REF! | C18: =+#REF! -> #REF! | D18: =+#REF! -> #REF! | E18: =+#REF! -> #REF! | F18: =+#REF! -> #REF! | G18: =+#REF! -> #REF! | H18: =+#REF! -> #REF! | I18: =+#REF! -> #REF! | J18: =+#REF! -> #REF! | ... M18: =+#REF! -> #REF! | N18: =+'Well Template'!$I21 | O18: =+#REF! -> #REF! | P18: =+#REF! -> #REF! | Q18: =+#REF! -> #REF! | R18: =+#REF! -> #REF! | S18: =+#REF! -> #REF! | T18: =+#REF! -> #REF! | U18: =+#REF! -> #REF! | V18: =+#REF! -> #REF! | ... Z18: =+#REF! -> #REF! | AA18: =SUM(B18:Z18) -> #REF!
A19: =+A18+1 -> 16 | B19: =#REF! -> #REF! | C19: =+#REF! -> #REF! | D19: =+#REF! -> #REF! | E19: =+#REF! -> #REF! | F19: =+#REF! -> #REF! | G19: =+#REF! -> #REF! | H19: =+#REF! -> #REF! | I19: =+#REF! -> #REF! | J19: =+#REF! -> #REF! | ... M19: =+#REF! -> #REF! | N19: =+'Well Template'!$I22 | O19: =+#REF! -> #REF! | P19: =+#REF! -> #REF! | Q19: =+#REF! -> #REF! | R19: =+#REF! -> #REF! | S19: =+#REF! -> #REF! | T19: =+#REF! -> #REF! | U19: =+#REF! -> #REF! | V19: =+#REF! -> #REF! | ... Z19: =+#REF! -> #REF! | AA19: =SUM(B19:Z19) -> #REF!
A20: =+A19+1 -> 17 | B20: =#REF! -> #REF! | C20: =+#REF! -> #REF! | D20: =+#REF! -> #REF! | E20: =+#REF! -> #REF! | F20: =+#REF! -> #REF! | G20: =+#REF! -> #REF! | H20: =+#REF! -> #REF! | I20: =+#REF! -> #REF! | J20: =+#REF! -> #REF! | ... M20: =+#REF! -> #REF! | N20: =+'Well Template'!$I23 | O20: =+#REF! -> #REF! | P20: =+#REF! -> #REF! | Q20: =+#REF! -> #REF! | R20: =+#REF! -> #REF! | S20: =+#REF! -> #REF! | T20: =+#REF! -> #REF! | U20: =+#REF! -> #REF! | V20: =+#REF! -> #REF! | ... Z20: =+#REF! -> #REF! | AA20: =SUM(B20:Z20) -> #REF!
A21: =+A20+1 -> 18 | B21: =#REF! -> #REF! | C21: =+#REF! -> #REF! | D21: =+#REF! -> #REF! | E21: =+#REF! -> #REF! | F21: =+#REF! -> #REF! | G21: =+#REF! -> #REF! | H21: =+#REF! -> #REF! | I21: =+#REF! -> #REF! | J21: =+#REF! -> #REF! | ... M21: =+#REF! -> #REF! | N21: =+'Well Template'!$I24 | O21: =+#REF! -> #REF! | P21: =+#REF! -> #REF! | Q21: =+#REF! -> #REF! | R21: =+#REF! -> #REF! | S21: =+#REF! -> #REF! | T21: =+#REF! -> #REF! | U21: =+#REF! -> #REF! | V21: =+#REF! -> #REF! | ... Z21: =+#REF! -> #REF! | AA21: =SUM(B21:Z21) -> #REF!
A22: =+A21+1 -> 19 | B22: =#REF! -> #REF! | C22: =+#REF! -> #REF! | D22: =+#REF! -> #REF! | E22: =+#REF! -> #REF! | F22: =+#REF! -> #REF! | G22: =+#REF! -> #REF! | H22: =+#REF! -> #REF! | I22: =+#REF! -> #REF! | J22: =+#REF! -> #REF! | ... M22: =+#REF! -> #REF! | N22: =+'Well Template'!$I25 | O22: =+#REF! -> #REF! | P22: =+#REF! -> #REF! | Q22: =+#REF! -> #REF! | R22: =+#REF! -> #REF! | S22: =+#REF! -> #REF! | T22: =+#REF! -> #REF! | U22: =+#REF! -> #REF! | V22: =+#REF! -> #REF! | ... Z22: =+#REF! -> #REF! | AA22: =SUM(B22:Z22) -> #REF!
A23: =+A22+1 -> 20 | B23: =#REF! -> #REF! | C23: =+#REF! -> #REF! | D23: =+#REF! -> #REF! | E23: =+#REF! -> #REF! | F23: =+#REF! -> #REF! | G23: =+#REF! -> #REF! | H23: =+#REF! -> #REF! | I23: =+#REF! -> #REF! | J23: =+#REF! -> #REF! | ... M23: =+#REF! -> #REF! | N23: =+'Well Template'!$I26 | O23: =+#REF! -> #REF! | P23: =+#REF! -> #REF! | Q23: =+#REF! -> #REF! | R23: =+#REF! -> #REF! | S23: =+#REF! -> #REF! | T23: =+#REF! -> #REF! | U23: =+#REF! -> #REF! | V23: =+#REF! -> #REF! | ... Z23: =+#REF! -> #REF! | AA23: =SUM(B23:Z23) -> #REF!
... A34: =+A33+1 -> 31 | B34: =#REF! -> #REF! | C34: =+#REF! -> #REF! | D34: =+#REF! -> #REF! | E34: =+#REF! -> #REF! | F34: =+#REF! -> #REF! | G34: =+#REF! -> #REF! | H34: =+#REF! -> #REF! | I34: =+#REF! -> #REF! | J34: =+#REF! -> #REF! | ... M34: =+#REF! -> #REF! | N34: =+'Well Template'!$I37 | O34: =+#REF! -> #REF! | P34: =+#REF! -> #REF! | Q34: =+#REF! -> #REF! | R34: =+#REF! -> #REF! | S34: =+#REF! -> #REF! | T34: =+#REF! -> #REF! | U34: =+#REF! -> #REF! | V34: =+#REF! -> #REF! | ... Z34: =+#REF! -> #REF! | AA34: =SUM(B34:Z34) -> #REF!
A35: Cum | B35: =#REF! -> #REF! | C35: =+#REF! -> #REF! | D35: =+#REF! -> #REF! | E35: =+#REF! -> #REF! | F35: =IF(#REF!="",0,#REF!*0.75) -> #REF! | G35: =+#REF! -> #REF! | H35: =+#REF! -> #REF! | I35: =+#REF! -> #REF! | J35: =+#REF! -> #REF! | K35: =+#REF! -> #REF! | L35: =+#REF! -> #REF! | M35: =+#REF! -> #REF! | N35: =+'Well Template'!$I38 -> 0 | O35: =+#REF! -> #REF! | P35: =+#REF! -> #REF! | Q35: =+#REF! -> #REF! | R35: =+#REF! -> #REF! | S35: =+#REF! -> #REF! | T35: =+#REF! -> #REF! | U35: =+#REF! -> #REF! | V35: =+#REF! -> #REF! | ... Z35: =+#REF! -> #REF! | AA35: =SUM(B35:Z35) -> #REF!
B37: NET OIL SHIPPED
A38: Date | B38: =B3 -> #REF! | C38: =C3 -> #REF! | D38: =D3 -> #REF! | E38: =E3 -> #REF! | F38: =F3 -> #REF! | G38: =G3 -> #REF! | H38: =H3 -> #REF! | I38: =I3 -> #REF! | ... Z38: =Z3 -> #REF! | AA38: TOTAL
A39: 1 | B39: =#REF! -> #REF! | C39: =+#REF! -> #REF! | D39: =+#REF! -> #REF! | E39: =+#REF! -> #REF! | F39: =+#REF! -> #REF! | G39: =+#REF! -> #REF! | H39: =+#REF! -> #REF! | I39: =+#REF! -> #REF! | J39: =+#REF! -> #REF! | ... M39: =+#REF! -> #REF! | N39: =+'Well Template'!$O7 | O39: =+#REF! -> #REF! | P39: =+#REF! -> #REF! | Q39: =+#REF! -> #REF! | R39: =+#REF! -> #REF! | S39: =+#REF! -> #REF! | T39: =+#REF! -> #REF! | U39: =+#REF! -> #REF! | V39: =+#REF! -> #REF! | ... Z39: =+#REF! -> #REF! | AA39: =SUM(B39:Z39) -> #REF!
A40: =+A39+1 -> 2 | B40: =#REF! -> #REF! | C40: =+#REF! -> #REF! | D40: =+#REF! -> #REF! | E40: =+#REF! -> #REF! | F40: =+#REF! -> #REF! | G40: =+#REF! -> #REF! | H40: =+#REF! -> #REF! | I40: =+#REF! -> #REF! | J40: =+#REF! -> #REF! | ... M40: =+#REF! -> #REF! | N40: =+'Well Template'!$O8 | O40: =+#REF! -> #REF! | P40: =+#REF! -> #REF! | Q40: =+#REF! -> #REF! | R40: =+#REF! -> #REF! | S40: =+#REF! -> #REF! | T40: =+#REF! -> #REF! | U40: =+#REF! -> #REF! | V40: =+#REF! -> #REF! | ... Z40: =+#REF! -> #REF! | AA40: =SUM(B40:Z40) -> #REF!
A41: =+A40+1 -> 3 | B41: =#REF! -> #REF! | C41: =+#REF! -> #REF! | D41: =+#REF! -> #REF! | E41: =+#REF! -> #REF! | F41: =+#REF! -> #REF! | G41: =+#REF! -> #REF! | H41: =+#REF! -> #REF! | I41: =+#REF! -> #REF! | J41: =+#REF! -> #REF! | ... M41: =+#REF! -> #REF! | N41: =+'Well Template'!$O9 | O41: =+#REF! -> #REF! | P41: =+#REF! -> #REF! | Q41: =+#REF! -> #REF! | R41: =+#REF! -> #REF! | S41: =+#REF! -> #REF! | T41: =+#REF! -> #REF! | U41: =+#REF! -> #REF! | V41: =+#REF! -> #REF! | ... Z41: =+#REF! -> #REF! | AA41: =SUM(B41:Z41) -> #REF!
A42: =+A41+1 -> 4 | B42: =#REF! -> #REF! | C42: =+#REF! -> #REF! | D42: =+#REF! -> #REF! | E42: =+#REF! -> #REF! | F42: =+#REF! -> #REF! | G42: =+#REF! -> #REF! | H42: =+#REF! -> #REF! | I42: =+#REF! -> #REF! | J42: =+#REF! -> #REF! | ... M42: =+#REF! -> #REF! | N42: =+'Well Template'!$O10 | O42: =+#REF! -> #REF! | P42: =+#REF! -> #REF! | Q42: =+#REF! -> #REF! | R42: =+#REF! -> #REF! | S42: =+#REF! -> #REF! | T42: =+#REF! -> #REF! | U42: =+#REF! -> #REF! | V42: =+#REF! -> #REF! | ... Z42: =+#REF! -> #REF! | AA42: =SUM(B42:Z42) -> #REF!
A43: =+A42+1 -> 5 | B43: =#REF! -> #REF! | C43: =+#REF! -> #REF! | D43: =+#REF! -> #REF! | E43: =+#REF! -> #REF! | F43: =+#REF! -> #REF! | G43: =+#REF! -> #REF! | H43: =+#REF! -> #REF! | I43: =+#REF! -> #REF! | J43: =+#REF! -> #REF! | ... M43: =+#REF! -> #REF! | N43: =+'Well Template'!$O11 | O43: =+#REF! -> #REF! | P43: =+#REF! -> #REF! | Q43: =+#REF! -> #REF! | R43: =+#REF! -> #REF! | S43: =+#REF! -> #REF! | T43: =+#REF! -> #REF! | U43: =+#REF! -> #REF! | V43: =+#REF! -> #REF! | ... Z43: =+#REF! -> #REF! | AA43: =SUM(B43:Z43) -> #REF!
A44: =+A43+1 -> 6 | B44: =#REF! -> #REF! | C44: =+#REF! -> #REF! | D44: =+#REF! -> #REF! | E44: =+#REF! -> #REF! | F44: =+#REF! -> #REF! | G44: =+#REF! -> #REF! | H44: =+#REF! -> #REF! | I44: =+#REF! -> #REF! | J44: =+#REF! -> #REF! | ... M44: =+#REF! -> #REF! | N44: =+'Well Template'!$O12 | O44: =+#REF! -> #REF! | P44: =+#REF! -> #REF! | Q44: =+#REF! -> #REF! | R44: =+#REF! -> #REF! | S44: =+#REF! -> #REF! | T44: =+#REF! -> #REF! | U44: =+#REF! -> #REF! | V44: =+#REF! -> #REF! | ... Z44: =+#REF! -> #REF! | AA44: =SUM(B44:Z44) -> #REF!
A45: =+A44+1 -> 7 | B45: =#REF! -> #REF! | C45: =+#REF! -> #REF! | D45: =+#REF! -> #REF! | E45: =+#REF! -> #REF! | F45: =+#REF! -> #REF! | G45: =+#REF! -> #REF! | H45: =+#REF! -> #REF! | I45: =+#REF! -> #REF! | J45: =+#REF! -> #REF! | ... M45: =+#REF! -> #REF! | N45: =+'Well Template'!$O13 | O45: =+#REF! -> #REF! | P45: =+#REF! -> #REF! | Q45: =+#REF! -> #REF! | R45: =+#REF! -> #REF! | S45: =+#REF! -> #REF! | T45: =+#REF! -> #REF! | U45: =+#REF! -> #REF! | V45: =+#REF! -> #REF! | ... Z45: =+#REF! -> #REF! | AA45: =SUM(B45:Z45) -> #REF!
A46: 8 | B46: =#REF! -> #REF! | C46: =+#REF! -> #REF! | D46: =+#REF! -> #REF! | E46: =+#REF! -> #REF! | F46: =+#REF! -> #REF! | G46: =+#REF! -> #REF! | H46: =+#REF! -> #REF! | I46: =+#REF! -> #REF! | J46: =+#REF! -> #REF! | ... M46: =+#REF! -> #REF! | N46: =+'Well Template'!$O14 | O46: =+#REF! -> #REF! | P46: =+#REF! -> #REF! | Q46: =+#REF! -> #REF! | R46: =+#REF! -> #REF! | S46: =+#REF! -> #REF! | T46: =+#REF! -> #REF! | U46: =+#REF! -> #REF! | V46: =+#REF! -> #REF! | ... Z46: =+#REF! -> #REF! | AA46: =SUM(B46:Z46) -> #REF!
A47: =+A46+1 -> 9 | B47: =#REF! -> #REF! | C47: =+#REF! -> #REF! | D47: =+#REF! -> #REF! | E47: =+#REF! -> #REF! | F47: =+#REF! -> #REF! | G47: =+#REF! -> #REF! | H47: =+#REF! -> #REF! | I47: =+#REF! -> #REF! | J47: =+#REF! -> #REF! | ... M47: =+#REF! -> #REF! | N47: =+'Well Template'!$O15 | O47: =+#REF! -> #REF! | P47: =+#REF! -> #REF! | Q47: =+#REF! -> #REF! | R47: =+#REF! -> #REF! | S47: =+#REF! -> #REF! | T47: =+#REF! -> #REF! | U47: =+#REF! -> #REF! | V47: =+#REF! -> #REF! | ... Z47: =+#REF! -> #REF! | AA47: =SUM(B47:Z47) -> #REF!
A48: =+A47+1 -> 10 | B48: =#REF! -> #REF! | C48: =+#REF! -> #REF! | D48: =+#REF! -> #REF! | E48: =+#REF! -> #REF! | F48: =+#REF! -> #REF! | G48: =+#REF! -> #REF! | H48: =+#REF! -> #REF! | I48: =+#REF! -> #REF! | J48: =+#REF! -> #REF! | ... M48: =+#REF! -> #REF! | N48: =+'Well Template'!$O16 | O48: =+#REF! -> #REF! | P48: =+#REF! -> #REF! | Q48: =+#REF! -> #REF! | R48: =+#REF! -> #REF! | S48: =+#REF! -> #REF! | T48: =+#REF! -> #REF! | U48: =+#REF! -> #REF! | V48: =+#REF! -> #REF! | ... Z48: =+#REF! -> #REF! | AA48: =SUM(B48:Z48) -> #REF!
A49: =+A48+1 -> 11 | B49: =#REF! -> #REF! | C49: =+#REF! -> #REF! | D49: =+#REF! -> #REF! | E49: =+#REF! -> #REF! | F49: =+#REF! -> #REF! | G49: =+#REF! -> #REF! | H49: =+#REF! -> #REF! | I49: =+#REF! -> #REF! | J49: =+#REF! -> #REF! | ... M49: =+#REF! -> #REF! | N49: =+'Well Template'!$O17 | O49: =+#REF! -> #REF! | P49: =+#REF! -> #REF! | Q49: =+#REF! -> #REF! | R49: =+#REF! -> #REF! | S49: =+#REF! -> #REF! | T49: =+#REF! -> #REF! | U49: =+#REF! -> #REF! | V49: =+#REF! -> #REF! | ... Z49: =+#REF! -> #REF! | AA49: =SUM(B49:Z49) -> #REF!
A50: =+A49+1 -> 12 | B50: =#REF! -> #REF! | C50: =+#REF! -> #REF! | D50: =+#REF! -> #REF! | E50: =+#REF! -> #REF! | F50: =+#REF! -> #REF! | G50: =+#REF! -> #REF! | H50: =+#REF! -> #REF! | I50: =+#REF! -> #REF! | J50: =+#REF! -> #REF! | ... M50: =+#REF! -> #REF! | N50: =+'Well Template'!$O18 | O50: =+#REF! -> #REF! | P50: =+#REF! -> #REF! | Q50: =+#REF! -> #REF! | R50: =+#REF! -> #REF! | S50: =+#REF! -> #REF! | T50: =+#REF! -> #REF! | U50: =+#REF! -> #REF! | V50: =+#REF! -> #REF! | ... Z50: =+#REF! -> #REF! | AA50: =SUM(B50:Z50) -> #REF!
A51: =+A50+1 -> 13 | B51: =#REF! -> #REF! | C51: =+#REF! -> #REF! | D51: =+#REF! -> #REF! | E51: =+#REF! -> #REF! | F51: =+#REF! -> #REF! | G51: =+#REF! -> #REF! | H51: =+#REF! -> #REF! | I51: =+#REF! -> #REF! | J51: =+#REF! -> #REF! | ... M51: =+#REF! -> #REF! | N51: =+'Well Template'!$O19 | O51: =+#REF! -> #REF! | P51: =+#REF! -> #REF! | Q51: =+#REF! -> #REF! | R51: =+#REF! -> #REF! | S51: =+#REF! -> #REF! | T51: =+#REF! -> #REF! | U51: =+#REF! -> #REF! | V51: =+#REF! -> #REF! | ... Z51: =+#REF! -> #REF! | AA51: =SUM(B51:Z51) -> #REF!
A52: =+A51+1 -> 14 | B52: =#REF! -> #REF! | C52: =+#REF! -> #REF! | D52: =+#REF! -> #REF! | E52: =+#REF! -> #REF! | F52: =+#REF! -> #REF! | G52: =+#REF! -> #REF! | H52: =+#REF! -> #REF! | I52: =+#REF! -> #REF! | J52: =+#REF! -> #REF! | ... M52: =+#REF! -> #REF! | N52: =+'Well Template'!$O20 | O52: =+#REF! -> #REF! | P52: =+#REF! -> #REF! | Q52: =+#REF! -> #REF! | R52: =+#REF! -> #REF! | S52: =+#REF! -> #REF! | T52: =+#REF! -> #REF! | U52: =+#REF! -> #REF! | V52: =+#REF! -> #REF! | ... Z52: =+#REF! -> #REF! | AA52: =SUM(B52:Z52) -> #REF!
...
